<mujoco model="single_arm_ophthalmic_trocar_sidecar">
  <compiler angle="radian" coordinate="local"/>
  <option timestep="0.002" gravity="0 0 0" integrator="implicitfast"/>

  <default>
    <joint damping="0.04" armature="0.002" limited="true"/>
    <geom margin="0.0002" solref="0.01 1" solimp="0.9 0.95 0.001"/>
  </default>

  <asset>
    <material name="arm_mat" rgba="0.55 0.62 0.68 1"/>
    <material name="tool_mat" rgba="0.08 0.08 0.09 1"/>
    <material name="port_mat" rgba="0.85 0.18 0.12 1"/>
    <material name="eye_mat" rgba="0.95 0.90 0.84 0.35"/>
  </asset>

  <worldbody>
    <light name="key_light" pos="0 -0.5 0.7" dir="0.2 0.7 -1"/>
    <geom name="ground" type="plane" pos="0 0 0" size="1 1 0.01" rgba="0.92 0.92 0.90 1" contype="0" conaffinity="0"/>

    <geom name="eye_surface" type="sphere" pos="0.352 0 0.16" size="0.012" material="eye_mat" contype="0" conaffinity="0"/>
    <geom name="port_wall_y_pos" type="box" pos="0.34 0.00075 0.16" size="0.00035 0.00025 0.00125" material="port_mat" contype="1" conaffinity="1"/>
    <geom name="port_wall_y_neg" type="box" pos="0.34 -0.00075 0.16" size="0.00035 0.00025 0.00125" material="port_mat" contype="1" conaffinity="1"/>
    <geom name="port_wall_z_pos" type="box" pos="0.34 0 0.16075" size="0.00035 0.00125 0.00025" material="port_mat" contype="1" conaffinity="1"/>
    <geom name="port_wall_z_neg" type="box" pos="0.34 0 0.15925" size="0.00035 0.00125 0.00025" material="port_mat" contype="1" conaffinity="1"/>

    <body name="base" pos="0 0 0.08">
      <geom name="base_geom" type="cylinder" size="0.045 0.025" material="arm_mat" contype="0" conaffinity="0"/>
      <body name="link1" pos="0 0 0.025">
        <joint name="j1" type="hinge" axis="0 0 1" range="-3.14 3.14"/>
        <geom name="link1_geom" type="capsule" fromto="0 0 0 0.055 0 0.035" size="0.012" material="arm_mat" contype="0" conaffinity="0"/>
        <body name="link2" pos="0.055 0 0.035">
          <joint name="j2" type="hinge" axis="0 1 0" range="-2.80 2.80"/>
          <geom name="link2_geom" type="capsule" fromto="0 0 0 0.085 0 0" size="0.010" material="arm_mat" contype="0" conaffinity="0"/>
          <body name="link3" pos="0.085 0 0">
            <joint name="j3" type="hinge" axis="0 1 0" range="-2.80 2.80"/>
            <geom name="link3_geom" type="capsule" fromto="0 0 0 0.075 0 0" size="0.009" material="arm_mat" contype="0" conaffinity="0"/>
            <body name="link4" pos="0.075 0 0">
              <joint name="j4" type="hinge" axis="1 0 0" range="-3.14 3.14"/>
              <geom name="link4_geom" type="capsule" fromto="0 0 0 0.050 0 0" size="0.008" material="arm_mat" contype="0" conaffinity="0"/>
              <body name="link5" pos="0.050 0 0">
                <joint name="j5" type="hinge" axis="0 1 0" range="-3.14 3.14"/>
                <geom name="link5_geom" type="capsule" fromto="0 0 0 0.040 0 0" size="0.007" material="arm_mat" contype="0" conaffinity="0"/>
                <body name="link6" pos="0.040 0 0">
                  <joint name="j6" type="hinge" axis="1 0 0" range="-3.14 3.14"/>
                  <geom name="link6_geom" type="capsule" fromto="0 0 0 0.030 0 0" size="0.006" material="arm_mat" contype="0" conaffinity="0"/>
                  <body name="instrument" pos="0.030 0 0">
                    <geom name="eye_in_hand_camera_body" type="box" pos="-0.010 0 0.010" size="0.005 0.004 0.003" rgba="0.02 0.02 0.025 1" contype="0" conaffinity="0"/>
                    <camera name="eye_in_hand" mode="fixed" pos="-0.010 0 0.010" xyaxes="0 -1 0 0 0 1" fovy="41.9741"/>
                    <geom name="instrument_shaft" type="capsule" fromto="0 0 0 0.055 0 0" size="0.000255" material="tool_mat" contype="1" conaffinity="1" density="7800"/>
                    <site name="tool_tip" pos="0.055 0 0" size="0.00055" rgba="0.05 0.2 1 1"/>
                  </body>
                </body>
              </body>
            </body>
          </body>
        </body>
      </body>
    </body>
  </worldbody>

  <actuator>
    <position name="a1" joint="j1" kp="450" ctrlrange="-3.14 3.14"/>
    <position name="a2" joint="j2" kp="450" ctrlrange="-2.80 2.80"/>
    <position name="a3" joint="j3" kp="450" ctrlrange="-2.80 2.80"/>
    <position name="a4" joint="j4" kp="300" ctrlrange="-3.14 3.14"/>
    <position name="a5" joint="j5" kp="300" ctrlrange="-3.14 3.14"/>
    <position name="a6" joint="j6" kp="250" ctrlrange="-3.14 3.14"/>
  </actuator>
</mujoco>
